<?xml version="1.0"?>
<robot  name="two_DOF_robot">

<!-- Used for fixing robot to Gazebo 'base_link' -->
  <link name="world"/>

  <joint name="glue_robot_to_world" type="fixed">
    <parent link="world"/>
    <child link="link1"/>
  </joint>

 <!-- Base Link -->
  <link name="link1">
    <collision>
      <origin xyz="0 0 0.5" rpy="0 0 0"/>
      <geometry>
       <box size="0.2 0.2 0.7"/>
      </geometry>
    </collision>

    <visual>
      <origin xyz="0 0 0.5" rpy="0 0 0"/>
      <geometry>
        <box size="0.2 0.2 1"/>
      </geometry>
    </visual>

    <inertial>
      <origin xyz="0 0 0.5" rpy="0 0 0"/>
      <mass value="1"/>
      <inertia
        ixx="1.0" ixy="0.0" ixz="0.0"
        iyy="1.0" iyz="0.0"
        izz="1.0"/>
    </inertial>
  </link>

<!-- Moveable Link -->
  <link name="link2">
    <collision>
      <origin xyz="0 0 0.5" rpy="0 0 0"/>
      <geometry>
        <cylinder length="1" radius="0.1"/>
        <!--box size="0.15 0.15 0.8"-->
      </geometry>
    </collision>

    <visual>
      <origin xyz="0 0 0.5" rpy="0 0 0"/>
      <geometry>
        <cylinder length="1" radius="0.1"/>
      </geometry>
    </visual>

    <inertial>
      <origin xyz="0 0 0.5" rpy="0 0 0"/>
      <mass value="1"/>
      <inertia
        ixx="0.1" ixy="0.0" ixz="0.0"
        iyy="0.1" iyz="0.0"
        izz="0.005"/>
    </inertial>
  </link>

  <joint name="joint1" type="continuous">
    <parent link="link1"/>
    <child link="link2"/>
    <origin xyz="0 0 1" rpy="0 0 0"/>
    <axis xyz="0 1 0"/>
  </joint>

<!-- Moveable Link -->
  <link name="link3">
    <collision>
      <origin xyz="0 0 0.5" rpy="0 0 0"/>
      <geometry>
        <cylinder length="0.6" radius="0.06"/>
        <!--box size="0.15 0.15 0.8"-->
      </geometry>
    </collision>

    <visual>
      <origin xyz="0 0 0.3" rpy="0 0 0"/>
      <geometry>
        <cylinder length="0.6" radius="0.06"/>
      </geometry>
    </visual>

    <inertial>
      <origin xyz="0 0 0.3" rpy="0 0 0"/>
      <mass value="0.6"/>
      <inertia
        ixx="0.06" ixy="0.0" ixz="0.0"
        iyy="0.6" iyz="0.0"
        izz="0.003"/>
    </inertial>
  </link>

  <joint name="joint2" type="continuous">
    <parent link="link2"/>
    <child link="link3"/>
    <origin xyz="0 0 1" rpy="0 0 0"/>
    <axis xyz="0 1 0"/>
  </joint>

</robot>

